Workbook

Sheet aktivnepesseg
A1: Ev | B1: Jaras | C1: azon | D1: Aktivkorunepesseg (jogszabályváltozások miatt eltérő, részletesen a leírásban!)
A2: 2001 | B2: Ajkai járás | C2: =A2&B2 -> 2001Ajkai járás | D2: 24835
A3: 2001 | B3: Aszódi járás | C3: =A3&B3 -> 2001Aszódi járás | D3: 21786
A4: 2001 | B4: Bácsalmási járás | C4: =A4&B4 -> 2001Bácsalmási járás | D4: 12459
A5: 2001 | B5: Bajai járás | C5: =A5&B5 -> 2001Bajai járás | D5: 39926
A6: 2001 | B6: Baktalórántházai járás | C6: =A6&B6 -> 2001Baktalórántházai járás | D6: 11177
A7: 2001 | B7: Balassagyarmati járás | C7: =A7&B7 -> 2001Balassagyarmati járás | D7: 24873
A8: 2001 | B8: Balatonalmádi járás | C8: =A8&B8 -> 2001Balatonalmádi járás | D8: 13478
A9: 2001 | B9: Balatonfüredi járás | C9: =A9&B9 -> 2001Balatonfüredi járás | D9: 13625
A10: 2001 | B10: Balmazújvárosi járás | C10: =A10&B10 -> 2001Balmazújvárosi járás | D10: 17506
A11: 2001 | B11: Barcsi járás | C11: =A11&B11 -> 2001Barcsi járás | D11: 15291
A12: 2001 | B12: Bátonyterenyei járás | C12: =A12&B12 -> 2001Bátonyterenyei járás | D12: 13773
A13: 2001 | B13: Békéscsabai járás | C13: =A13&B13 -> 2001Békéscsabai járás | D13: 53185
... A793: 2024 | B793: Budapest | C793: =A793&B793 -> 2024Budapest | D793: 1056928
A1296: 1 | B1296: 1 | C1296: 1 | D1296: 1

Sheet medianjov_szamitas
C1: 2001 | D1: 2011 | E1: 2022 | F1: 2024
A2: medián alatti vágópont | B2: értéke | C2: 600 | D2: 1200 | E2: 3000 | F2: 4000
B3: kumulatív eloszlás adózók között | C3: 0.45814732 | D3: 0.49899675 | E3: 0.42369324 | F3: 0.44669152
A4: medián feletti vágópont | B4: értéke | C4: 700 | D4: 1500 | E4: 4000 | F4: 5000
B5: kumulatív eloszlás adózók között | C5: 0.52409219 | D5: 0.59902222 | E5: 0.57942173 | F5: 0.54402653
A6: abszolút eltérés | B6: medián alatt | C6: =ABS(C3-0.5) -> 0.041852684 | D6: =ABS(D3-0.5) -> 0.0010032458 | E6: =ABS(E3-0.5) -> 0.076306761 | F6: =ABS(F3-0.5) -> 0.053308485
B7: medián felett | C7: =ABS(C5-0.5) -> 0.024092186 | D7: =ABS(D5-0.5) -> 0.09902222 | E7: =ABS(E5-0.5) -> 0.079421727 | F7: =ABS(F5-0.5) -> 0.044026527
B8: összesen | C8: =C7+C6 -> 0.06594487 | D8: =D7+D6 -> 0.10002547 | E8: =E7+E6 -> 0.15572849 | F8: =F7+F6 -> 0.097335011
A9: Vágópontok súlya | B9: medián alatti vágópont | C9: =1-C6/C8 -> 0.36533829 | D9: =1-D6/D8 -> 0.9899701 | E9: =1-E6/E8 -> 0.51000127 | F9: =1-F6/F8 -> 0.45231953
B10: medián feletti vágópont | C10: =1-C7/C8 -> 0.63466171 | D10: =1-D7/D8 -> 0.010029904 | E10: =1-E7/E8 -> 0.48999873 | F10: =1-F7/F8 -> 0.54768047
A11: Medián becslése | C11: =C9*C2+C10*C4 -> 663.46617 | D11: =D9*D2+D10*D4 -> 1203.009 | E11: =E9*E2+E10*E4 -> 3489.9987 | F11: =F9*F2+F10*F4 -> 4547.6805
A12: Küszöbérték | B12: Medián 60%-a | C12: =C11*0.6 -> 398.0797 | D12: =D11*0.6 -> 721.80538 | E12: =E11*0.6 -> 2093.9992 | F12: =F11*0.6 -> 2728.6083
B13: küszöbértékhez legközelebb eső vágópont | C13: 400 | D13: 800 | E13: 2000 | F13: 2500
A14: Alternatív küszöbértékek | B14: Medián 70%-a | C14: =C11*0.7 -> 464.42632 | D14: =D11*0.7 -> 842.10628 | E14: =E11*0.7 -> 2442.9991 | F14: =F11*0.7 -> 3183.3763
B15: küszöbértékhez legközelebb eső vágópont | C15: 500 | D15: 800 | E15: 2500 | F15: 3000
B16: RÉGI VÁGÓPONTOK | C16: 500 | D16: 1000 | E16: 2000 | F16: 3000

Sheet kuszobATTEKINTESesOrszagosRata
H1: korrelációk
C2: 2001 | D2: 2011 | E2: 2022 | F2: 2024 | H2: cor2001-2011 | I2: cor2001-2022 | J2: cor2001-2024
A3: régi verzió | B3: köszöb | C3: 500 | D3: 1000 | E3: 2000 | F3: 3000 | G3: rangkorreláció | H3: 0.84878778 | I3: 0.60714207 | J3: 0.67641713
B4: országos ráta | C4: 0.37183 | D4: 0.4332308 | E4: 0.35045002 | F4: 0.37781742 | G4: korreláció | H4: 0.84988039 | I4: 0.57342845 | J4: 0.66850997
A5: medián60 | B5: küszöb | C5: 400 | D5: 800 | E5: 2000 | F5: 2500 | G5: rangkorreláció | H5: 0.83943601 | I5: 0.60875721 | J5: 0.65321034
B6: országos ráta | C6: 0.34477481 | D6: 0.40868059 | E6: 0.35045002 | F6: 0.36248433 | G6: korreláció | H6: 0.83733087 | I6: 0.57782098 | J6: 0.64540763
A7: medián70 | B7: küszöb | C7: 500 | D7: 800 | E7: 2500 | F7: 3000 | G7: rangkorreláció | H7: 0.83850365 | I7: 0.63073499 | J7: 0.67641713
B8: országos ráta | C8: 0.37183 | D8: 0.40868059 | E8: 0.37308722 | F8: 0.37781742 | G8: korreláció | H8: 0.83536744 | I8: 0.61110106 | J8: 0.66850997
A10: a szürkével jelöltek alternatív küszöbértékek

Sheet P1long_allversionS
A1: jaras | B1: ev | C1: jarasev | D1: P1med60 | E1: rangMED60 | F1: rang3MED60
A2: Ajkai járás | B2: 2001 | C2: =A2&B2 -> Ajkai járás2001 | D2: 0.24542984 | E2: 14 | F2: =IF(E2<66,1,IF(E2<132,2,3)) -> 1
A3: Aszódi járás | B3: 2001 | C3: =A3&B3 -> Aszódi járás2001 | D3: 0.38885638 | E3: 124 | F3: =IF(E3<66,1,IF(E3<132,2,3)) -> 2
A4: Bácsalmási járás | B4: 2001 | C4: =A4&B4 -> Bácsalmási járás2001 | D4: 0.4119813 | E4: 147 | F4: =IF(E4<66,1,IF(E4<132,2,3)) -> 3
A5: Bajai járás | B5: 2001 | C5: =A5&B5 -> Bajai járás2001 | D5: 0.37357862 | E5: 112 | F5: =IF(E5<66,1,IF(E5<132,2,3)) -> 2
A6: Baktalórántházai járás | B6: 2001 | C6: =A6&B6 -> Baktalórántházai járás2001 | D6: 0.52359757 | E6: 196 | F6: =IF(E6<66,1,IF(E6<132,2,3)) -> 3
A7: Balassagyarmati járás | B7: 2001 | C7: =A7&B7 -> Balassagyarmati járás2001 | D7: 0.4297833 | E7: 160 | F7: =IF(E7<66,1,IF(E7<132,2,3)) -> 3
A8: Balatonalmádi járás | B8: 2001 | C8: =A8&B8 -> Balatonalmádi járás2001 | D8: 0.24564104 | E8: 15 | F8: =IF(E8<66,1,IF(E8<132,2,3)) -> 1
A9: Balatonfüredi járás | B9: 2001 | C9: =A9&B9 -> Balatonfüredi járás2001 | D9: 0.22206422 | E9: 7 | F9: =IF(E9<66,1,IF(E9<132,2,3)) -> 1
A10: Balmazújvárosi járás | B10: 2001 | C10: =A10&B10 -> Balmazújvárosi járás2001 | D10: 0.36955901 | E10: 109 | F10: =IF(E10<66,1,IF(E10<132,2,3)) -> 2
A11: Barcsi járás | B11: 2001 | C11: =A11&B11 -> Barcsi járás2001 | D11: 0.43367831 | E11: 163 | F11: =IF(E11<66,1,IF(E11<132,2,3)) -> 3
A12: Bátonyterenyei járás | B12: 2001 | C12: =A12&B12 -> Bátonyterenyei járás2001 | D12: 0.43782219 | E12: 164 | F12: =IF(E12<66,1,IF(E12<132,2,3)) -> 3
A13: Békéscsabai járás | B13: 2001 | C13: =A13&B13 -> Békéscsabai járás2001 | D13: 0.3160219 | E13: 60 | F13: =IF(E13<66,1,IF(E13<132,2,3)) -> 1
... A395: Zirci járás | B395: 2011 | C395: =A395&B395 -> Zirci járás2011 | D395: 0.32866244 | E395: 10 | F395: =IF(E395<66,1,IF(E395<132,2,3)) -> 1
A396: Ajkai járás | B396: 2022 | C396: =A396&B396 -> Ajkai járás2022 | D396: =#REF! -> #REF! | E396: 14 | F396: =IF(E396<66,1,IF(E396<132,2,3)) -> 1
A397: Aszódi járás | B397: 2022 | C397: =A397&B397 -> Aszódi járás2022 | D397: =#REF! -> #REF! | E397: 65 | F397: =IF(E397<66,1,IF(E397<132,2,3)) -> 1
A398: Bácsalmási járás | B398: 2022 | C398: =A398&B398 -> Bácsalmási járás2022 | D398: =#REF! -> #REF! | E398: 166 | F398: =IF(E398<66,1,IF(E398<132,2,3)) -> 3
A399: Bajai járás | B399: 2022 | C399: =A399&B399 -> Bajai járás2022 | D399: =#REF! -> #REF! | E399: 136 | F399: =IF(E399<66,1,IF(E399<132,2,3)) -> 3
A400: Baktalórántházai járás | B400: 2022 | C400: =A400&B400 -> Baktalórántházai járás2022 | D400: =#REF! -> #REF! | E400: 157 | F400: =IF(E400<66,1,IF(E400<132,2,3)) -> 3
A401: Balassagyarmati járás | B401: 2022 | C401: =A401&B401 -> Balassagyarmati járás2022 | D401: =#REF! -> #REF! | E401: 51 | F401: =IF(E401<66,1,IF(E401<132,2,3)) -> 1
A402: Balatonalmádi járás | B402: 2022 | C402: =A402&B402 -> Balatonalmádi járás2022 | D402: =#REF! -> #REF! | E402: 5 | F402: =IF(E402<66,1,IF(E402<132,2,3)) -> 1
A403: Balatonfüredi járás | B403: 2022 | C403: =A403&B403 -> Balatonfüredi járás2022 | D403: =#REF! -> #REF! | E403: 13 | F403: =IF(E403<66,1,IF(E403<132,2,3)) -> 1
A404: Balmazújvárosi járás | B404: 2022 | C404: =A404&B404 -> Balmazújvárosi járás2022 | D404: =#REF! -> #REF! | E404: 120 | F404: =IF(E404<66,1,IF(E404<132,2,3)) -> 2
A405: Barcsi járás | B405: 2022 | C405: =A405&B405 -> Barcsi járás2022 | D405: =#REF! -> #REF! | E405: 186 | F405: =IF(E405<66,1,IF(E405<132,2,3)) -> 3
A406: Bátonyterenyei járás | B406: 2022 | C406: =A406&B406 -> Bátonyterenyei járás2022 | D406: =#REF! -> #REF! | E406: 112 | F406: =IF(E406<66,1,IF(E406<132,2,3)) -> 2
A407: Békéscsabai járás | B407: 2022 | C407: =A407&B407 -> Békéscsabai járás2022 | D407: =#REF! -> #REF! | E407: 26 | F407: =IF(E407<66,1,IF(E407<132,2,3)) -> 1
... A592: Zirci járás | B592: 2022 | C592: =A592&B592 -> Zirci járás2022 | D592: =#REF! -> #REF! | E592: 6 | F592: =IF(E592<66,1,IF(E592<132,2,3)) -> 1
A593: Ajkai járás | B593: 2024 | C593: =A593&B593 -> Ajkai járás2024 | D593: 0.3200313 | E593: 44 | F593: =IF(E593<66,1,IF(E593<132,2,3)) -> 1
A594: Aszódi járás | B594: 2024 | C594: =A594&B594 -> Aszódi járás2024 | D594: 0.33675663 | E594: 59 | F594: =IF(E594<66,1,IF(E594<132,2,3)) -> 1
A595: Bácsalmási járás | B595: 2024 | C595: =A595&B595 -> Bácsalmási járás2024 | D595: 0.46772636 | E595: 175 | F595: =IF(E595<66,1,IF(E595<132,2,3)) -> 3
A596: Bajai járás | B596: 2024 | C596: =A596&B596 -> Bajai járás2024 | D596: 0.42961141 | E596: 146 | F596: =IF(E596<66,1,IF(E596<132,2,3)) -> 3
A597: Baktalórántházai járás | B597: 2024 | C597: =A597&B597 -> Baktalórántházai járás2024 | D597: 0.44722117 | E597: 159 | F597: =IF(E597<66,1,IF(E597<132,2,3)) -> 3
A598: Balassagyarmati járás | B598: 2024 | C598: =A598&B598 -> Balassagyarmati járás2024 | D598: 0.3465682 | E598: 68 | F598: =IF(E598<66,1,IF(E598<132,2,3)) -> 2
A599: Balatonalmádi járás | B599: 2024 | C599: =A599&B599 -> Balatonalmádi járás2024 | D599: 0.32627283 | E599: 49 | F599: =IF(E599<66,1,IF(E599<132,2,3)) -> 1
A600: Balatonfüredi járás | B600: 2024 | C600: =A600&B600 -> Balatonfüredi járás2024 | D600: 0.34451404 | E600: 67 | F600: =IF(E600<66,1,IF(E600<132,2,3)) -> 2
A601: Balmazújvárosi járás | B601: 2024 | C601: =A601&B601 -> Balmazújvárosi járás2024 | D601: 0.39864403 | E601: 113 | F601: =IF(E601<66,1,IF(E601<132,2,3)) -> 2
A602: Barcsi járás | B602: 2024 | C602: =A602&B602 -> Barcsi járás2024 | D602: 0.51521264 | E602: 193 | F602: =IF(E602<66,1,IF(E602<132,2,3)) -> 3
A603: Bátonyterenyei járás | B603: 2024 | C603: =A603&B603 -> Bátonyterenyei járás2024 | D603: 0.40962394 | E603: 122 | F603: =IF(E603<66,1,IF(E603<132,2,3)) -> 2
A604: Békéscsabai járás | B604: 2024 | C604: =A604&B604 -> Békéscsabai járás2024 | D604: 0.34776835 | E604: 69 | F604: =IF(E604<66,1,IF(E604<132,2,3)) -> 2
... A789: Zirci járás | B789: 2024 | C789: =A789&B789 -> Zirci járás2024 | D789: 0.30352043 | E789: 22 | F789: =IF(E789<66,1,IF(E789<132,2,3)) -> 1

Sheet 2001_60
A1: KÜSZÖB | D1: Adósáv alja | E1: 0 | F1: 0 | G1: =F2 -> 100 | H1: =G2 -> 200 | I1: 300 | J1: =I2 -> 400 | K1: =J2 -> 500 | L1: =K2 -> 600 | M1: =L2 -> 700 | N1: =M2 -> 800 | O1: =N2 -> 900 | P1: =O2 -> 1000 | Q1: =P2 -> 1500 | ... T1: =S2 -> 5000 | U1: V03 - alacsonyabb küszöb | AB1: Median60 szerinti küszöb
A2: 700 | D2: Adósáv teteje | E2: 0 | F2: 100 | G2: 200 | H2: 300 | I2: 400 | J2: 500 | K2: 600 | L2: 700 | M2: 800 | N2: 900 | O2: 1000 | P2: 1500 | Q2: 2000 | R2: 2500 | S2: 5000 | T2: =T1*1.5 -> 7500 | U2: AKTÍV KORÚAKHOZ
A3: 500 | D3: Adósáv közepe | E3: 0 | F3: =AVERAGE(F1:F2) -> 50 | G3: =AVERAGE(G1:G2) -> 150 | H3: =AVERAGE(H1:H2) -> 250 | I3: =AVERAGE(I1:I2) -> 350 | J3: =AVERAGE(J1:J2) -> 450 | K3: =AVERAGE(K1:K2) -> 550 | L3: =AVERAGE(L1:L2) -> 650 | M3: =AVERAGE(M1:M2) -> 750 | ... T3: =AVERAGE(T1:T2) -> 6250 | U3: 1 | V3: 1 | W3: 1 | X3: 1 | Y3: 1 | Z3: 1
A4: 400 | D4: szorzóP1v0102 | E4: =($A$2-E3)/$A$2 -> 1 | F4: =($A$2-F3)/$A$2 -> 0.92857143 | G4: =($A$2-G3)/$A$2 -> 0.78571429 | H4: =($A$2-H3)/$A$2 -> 0.64285714 | I4: =($A$2-I3)/$A$2 -> 0.5 | J4: =($A$2-J3)/$A$2 -> 0.35714286 | K4: =($A$2-K3)/$A$2 -> 0.21428571 | L4: =($A$2-L3)/$A$2 -> 0.071428571 | U4: P1 részeredmények
A5: a szürkével jelöltek alternatív küszöbértékek | D5: szorzóP1v03 | E5: =($A$3-E3)/$A$3 -> 1 | F5: =($A$3-F3)/$A$3 -> 0.9 | G5: =($A$3-G3)/$A$3 -> 0.7 | H5: =($A$3-H3)/$A$3 -> 0.5 | I5: =($A$3-I3)/$A$3 -> 0.3 | J5: =($A$3-J3)/$A$3 -> 0.1
D6: szorzóP1median60 | E6: 1 | F6: =($A$4-F3)/$A$4 -> 0.875 | G6: =($A$4-G3)/$A$4 -> 0.625 | H6: =($A$4-H3)/$A$4 -> 0.375 | I6: =($A$4-I3)/$A$4 -> 0.125
B7: kod | C7: aktivkoru | D7: összes adózó | E7: NULLA sávon adózó aktív korú | F7: 2001 SZJA adófizető; 0-100 000 Ft éves összevont adóalapba tartozó jövedelmi sávon (fő) | G7: 2001 SZJA adófizető; 100 001-200 000 Ft éves összevont adóalapba tartozó jövedelmi sávon (fő) | H7: 2001 SZJA adófizető; 200 001-300 000 Ft éves összevont adóalapba tartozó jövedelmi sávon (fő) | I7: 2001 SZJA adófizető; 300 001-400 000 Ft éves összevont adóalapba tartozó jövedelmi sávon (fő) | J7: 2001 SZJA adófizető; 400 001-500 000 Ft éves összevont adóalapba tartozó jövedelmi sávon (fő) | K7: 2001 SZJA adófizető; 500 001-600 000 Ft éves összevont adóalapba tartozó jövedelmi sávon (fő) | L7: 2001 SZJA adófizető; 600 001-700 000 Ft éves összevont adóalapba tartozó jövedelmi sávon (fő) | M7: 2001 SZJA adófizető; 700 001-800 000 Ft éves összevont adóalapba tartozó jövedelmi sávon (fő) | N7: 2001 SZJA adófizető; 800 001-900 000 Ft éves összevont adóalapba tartozó jövedelmi sávon (fő) | O7: 2001 SZJA adófizető; 900 001-1 000 000 Ft éves összevont adóalapba tartozó jövedelmi sávon (fő) | P7: 2001 SZJA adófizető; 1 000 001-1 500 000 Ft éves összevont adóalapba tartozó jövedelmi sávon (fő) | Q7: 2001 SZJA adófizető; 1 500 001-2 000 000 Ft éves összevont adóalapba tartozó jövedelmi sávon (fő) | R7: 2001 SZJA adófizető; 2 000 001-2 500 000 Ft éves összevont adóalapba tartozó jövedelmi sávon (fő) | S7: 2001 SZJA adófizető; 2 500 001-5 000 000 Ft éves összevont adóalapba tartozó jövedelmi sávon (fő) | T7: 2001 SZJA adófizető; 5 000 000-X Ft éves összevont adóalapba tartozó jövedelmi sávon (fő) | U7: 0-0 sáv (új jöv sáv!) | V7: 0-100 | W7: 100-200 | X7: 200-300 | Y7: 300-400 | Z7: 400-500 | AA7: P1 (0-1 jöv sávval) | AB7: 0-0 sáv (új jöv sáv!) | AC7: 0-100 | AD7: 100-200 | AE7: 200-300 | AF7: 300-400 | AG7: P1 (0-1 jöv sávval)
A8: Ajkai járás | B8: 183 | C8: =VLOOKUP(CONCATENATE("2001",'2001_60'!A8),aktivnepesseg!$C$2:$D$2226,2,FALSE) -> 24835 | D8: =SUM(F8:T8) -> 20670 | E8: =C8-D8 -> 4165 | F8: 1274 | G8: 573 | H8: 904 | I8: 947 | J8: 2593 | K8: 1950 | L8: 1668 | M8: 1484 | N8: 1289 | O8: 1187 | P8: 3831 | Q8: 1554 | R8: 633 | S8: 669 | T8: 114 | U8: =E8*E$5 -> 4165 | V8: =F8*F$5 -> 1146.6 | W8: =G8*G$5 -> 401.1 | X8: =H8*H$5 -> 452 | Y8: =I8*I$5 -> 284.1 | Z8: =J8*J$5 -> 259.3 | AA8: =SUM(U8:Z8)/$C8 -> 0.2701067 | AB8: =E8*E$6 -> 4165 | AC8: =F8*F$6 -> 1114.75 | AD8: =G8*G$6 -> 358.125 | AE8: =H8*H$6 -> 339 | AF8: =I8*I$6 -> 118.375 | AG8: =SUM(AB8:AF8)/$C8 -> 0.24542984
A9: Aszódi járás | B9: 122 | C9: =VLOOKUP(CONCATENATE("2001",'2001_60'!A9),aktivnepesseg!$C$2:$D$2226,2,FALSE) -> 21786 | D9: =SUM(F9:T9) -> 14643 | E9: =C9-D9 -> 7143 | F9: 759 | G9: 438 | H9: 734 | I9: 924 | J9: 2462 | K9: 1229 | L9: 898 | M9: 813 | N9: 807 | O9: 788 | P9: 2765 | Q9: 1089 | R9: 429 | S9: 441 | T9: 67 | U9: =E9*E$5 -> 7143 | V9: =F9*F$5 -> 683.1 | W9: =G9*G$5 -> 306.6 | X9: =H9*H$5 -> 367 | Y9: =I9*I$5 -> 277.2 | Z9: =J9*J$5 -> 246.2 | AA9: =SUM(U9:Z9)/$C9 -> 0.41416965 | AB9: =E9*E$6 -> 7143 | AC9: =F9*F$6 -> 664.125 | AD9: =G9*G$6 -> 273.75 | AE9: =H9*H$6 -> 275.25 | AF9: =I9*I$6 -> 115.5 | AG9: =SUM(AB9:AF9)/$C9 -> 0.38885638
A10: Bácsalmási járás | B10: 34 | C10: =VLOOKUP(CONCATENATE("2001",'2001_60'!A10),aktivnepesseg!$C$2:$D$2226,2,FALSE) -> 12459 | D10: =SUM(F10:T10) -> 8699 | E10: =C10-D10 -> 3760 | F10: 858 | G10: 470 | H10: 631 | I10: 734 | J10: 1249 | K10: 1000 | L10: 696 | M10: 630 | N10: 538 | O10: 407 | P10: 1009 | Q10: 255 | R10: 100 | S10: 107 | T10: 15 | U10: =E10*E$5 -> 3760 | V10: =F10*F$5 -> 772.2 | W10: =G10*G$5 -> 329 | X10: =H10*H$5 -> 315.5 | Y10: =I10*I$5 -> 220.2 | Z10: =J10*J$5 -> 124.9 | AA10: =SUM(U10:Z10)/$C10 -> 0.44319769 | AB10: =E10*E$6 -> 3760 | AC10: =F10*F$6 -> 750.75 | AD10: =G10*G$6 -> 293.75 | AE10: =H10*H$6 -> 236.625 | AF10: =I10*I$6 -> 91.75 | AG10: =SUM(AB10:AF10)/$C10 -> 0.4119813
A11: Bajai járás | B11: 35 | C11: =VLOOKUP(CONCATENATE("2001",'2001_60'!A11),aktivnepesseg!$C$2:$D$2226,2,FALSE) -> 39926 | D11: =SUM(F11:T11) -> 29079 | E11: =C11-D11 -> 10847 | F11: 2614 | G11: 1190 | H11: 2038 | I11: 2186 | J11: 4997 | K11: 2796 | L11: 2013 | M11: 1747 | N11: 1565 | O11: 1449 | P11: 3724 | Q11: 1264 | R11: 634 | S11: 747 | T11: 115 | U11: =E11*E$5 -> 10847 | V11: =F11*F$5 -> 2352.6 | W11: =G11*G$5 -> 833 | X11: =H11*H$5 -> 1019 | Y11: =I11*I$5 -> 655.8 | Z11: =J11*J$5 -> 499.7 | AA11: =SUM(U11:Z11)/$C11 -> 0.40592847 | AB11: =E11*E$6 -> 10847 | AC11: =F11*F$6 -> 2287.25 | AD11: =G11*G$6 -> 743.75 | AE11: =H11*H$6 -> 764.25 | AF11: =I11*I$6 -> 273.25 | AG11: =SUM(AB11:AF11)/$C11 -> 0.37357862
A12: Baktalórántházai járás | B12: 148 | C12: =VLOOKUP(CONCATENATE("2001",'2001_60'!A12),aktivnepesseg!$C$2:$D$2226,2,FALSE) -> 11177 | D12: =SUM(F12:T12) -> 6405 | E12: =C12-D12 -> 4772 | F12: 593 | G12: 414 | H12: 574 | I12: 699 | J12: 1135 | K12: 657 | L12: 495 | M12: 338 | N12: 246 | O12: 244 | P12: 624 | Q12: 232 | R12: 85 | S12: 69 | T12: 0 | U12: =E12*E$5 -> 4772 | V12: =F12*F$5 -> 533.7 | W12: =G12*G$5 -> 289.8 | X12: =H12*H$5 -> 287 | Y12: =I12*I$5 -> 209.7 | Z12: =J12*J$5 -> 113.5 | AA12: =SUM(U12:Z12)/$C12 -> 0.55522054 | AB12: =E12*E$6 -> 4772 | AC12: =F12*F$6 -> 518.875 | AD12: =G12*G$6 -> 258.75 | AE12: =H12*H$6 -> 215.25 | AF12: =I12*I$6 -> 87.375 | AG12: =SUM(AB12:AF12)/$C12 -> 0.52359757
A13: Balassagyarmati járás | B13: 116 | C13: =VLOOKUP(CONCATENATE("2001",'2001_60'!A13),aktivnepesseg!$C$2:$D$2226,2,FALSE) -> 24873 | D13: =SUM(F13:T13) -> 16054 | E13: =C13-D13 -> 8819 | F13: 1179 | G13: 587 | H13: 895 | I13: 1095 | J13: 2528 | K13: 1342 | L13: 1070 | M13: 1005 | N13: 878 | O13: 797 | P13: 2638 | Q13: 955 | R13: 420 | S13: 576 | T13: 89 | U13: =E13*E$5 -> 8819 | V13: =F13*F$5 -> 1061.1 | W13: =G13*G$5 -> 410.9 | X13: =H13*H$5 -> 447.5 | Y13: =I13*I$5 -> 328.5 | Z13: =J13*J$5 -> 252.8 | AA13: =SUM(U13:Z13)/$C13 -> 0.45510393 | AB13: =E13*E$6 -> 8819 | AC13: =F13*F$6 -> 1031.625 | AD13: =G13*G$6 -> 366.875 | AE13: =H13*H$6 -> 335.625 | AF13: =I13*I$6 -> 136.875 | AG13: =SUM(AB13:AF13)/$C13 -> 0.4297833
A14: Balatonalmádi járás | B14: 184 | C14: =VLOOKUP(CONCATENATE("2001",'2001_60'!A14),aktivnepesseg!$C$2:$D$2226,2,FALSE) -> 13478 | D14: =SUM(F14:T14) -> 11498 | E14: =C14-D14 -> 1980 | F14: 870 | G14: 392 | H14: 637 | I14: 685 | J14: 1749 | K14: 1049 | L14: 847 | M14: 807 | N14: 742 | O14: 595 | P14: 1630 | Q14: 695 | R14: 320 | S14: 393 | T14: 87 | U14: =E14*E$5 -> 1980 | V14: =F14*F$5 -> 783 | W14: =G14*G$5 -> 274.4 | X14: =H14*H$5 -> 318.5 | Y14: =I14*I$5 -> 205.5 | Z14: =J14*J$5 -> 174.9 | AA14: =SUM(U14:Z14)/$C14 -> 0.27721472 | AB14: =E14*E$6 -> 1980 | AC14: =F14*F$6 -> 761.25 | AD14: =G14*G$6 -> 245 | AE14: =H14*H$6 -> 238.875 | AF14: =I14*I$6 -> 85.625 | AG14: =SUM(AB14:AF14)/$C14 -> 0.24564104
A15: Balatonfüredi járás | B15: 185 | C15: =VLOOKUP(CONCATENATE("2001",'2001_60'!A15),aktivnepesseg!$C$2:$D$2226,2,FALSE) -> 13625 | D15: =SUM(F15:T15) -> 12341 | E15: =C15-D15 -> 1284 | F15: 1223 | G15: 448 | H15: 743 | I15: 903 | J15: 2219 | K15: 1132 | L15: 858 | M15: 706 | N15: 604 | O15: 532 | P15: 1444 | Q15: 660 | R15: 304 | S15: 468 | T15: 97 | U15: =E15*E$5 -> 1284 | V15: =F15*F$5 -> 1100.7 | W15: =G15*G$5 -> 313.6 | X15: =H15*H$5 -> 371.5 | Y15: =I15*I$5 -> 270.9 | Z15: =J15*J$5 -> 221.9 | AA15: =SUM(U15:Z15)/$C15 -> 0.26147523 | AB15: =E15*E$6 -> 1284 | AC15: =F15*F$6 -> 1070.125 | AD15: =G15*G$6 -> 280 | AE15: =H15*H$6 -> 278.625 | AF15: =I15*I$6 -> 112.875 | AG15: =SUM(AB15:AF15)/$C15 -> 0.22206422
A16: Balmazújvárosi járás | B16: 93 | C16: =VLOOKUP(CONCATENATE("2001",'2001_60'!A16),aktivnepesseg!$C$2:$D$2226,2,FALSE) -> 17506 | D16: =SUM(F16:T16) -> 12882 | E16: =C16-D16 -> 4624 | F16: 1159 | G16: 565 | H16: 901 | I16: 1123 | J16: 2409 | K16: 1488 | L16: 1000 | M16: 883 | N16: 709 | O16: 556 | P16: 1338 | Q16: 398 | R16: 162 | S16: 174 | T16: 17 | U16: =E16*E$5 -> 4624 | V16: =F16*F$5 -> 1043.1 | W16: =G16*G$5 -> 395.5 | X16: =H16*H$5 -> 450.5 | Y16: =I16*I$5 -> 336.9 | Z16: =J16*J$5 -> 240.9 | AA16: =SUM(U16:Z16)/$C16 -> 0.40505541 | AB16: =E16*E$6 -> 4624 | AC16: =F16*F$6 -> 1014.125 | AD16: =G16*G$6 -> 353.125 | AE16: =H16*H$6 -> 337.875 | AF16: =I16*I$6 -> 140.375 | AG16: =SUM(AB16:AF16)/$C16 -> 0.36955901
A17: Barcsi járás | B17: 140 | C17: =VLOOKUP(CONCATENATE("2001",'2001_60'!A17),aktivnepesseg!$C$2:$D$2226,2,FALSE) -> 15291 | D17: =SUM(F17:T17) -> 9960 | E17: =C17-D17 -> 5331 | F17: 731 | G17: 477 | H17: 709 | I17: 774 | J17: 1432 | K17: 1182 | L17: 857 | M17: 795 | N17: 598 | O17: 401 | P17: 1268 | Q17: 415 | R17: 153 | S17: 152 | T17: 16 | U17: =E17*E$5 -> 5331 | V17: =F17*F$5 -> 657.9 | W17: =G17*G$5 -> 333.9 | X17: =H17*H$5 -> 354.5 | Y17: =I17*I$5 -> 232.2 | Z17: =J17*J$5 -> 143.2 | AA17: =SUM(U17:Z17)/$C17 -> 0.4612321 | AB17: =E17*E$6 -> 5331 | AC17: =F17*F$6 -> 639.625 | AD17: =G17*G$6 -> 298.125 | AE17: =H17*H$6 -> 265.875 | AF17: =I17*I$6 -> 96.75 | AG17: =SUM(AB17:AF17)/$C17 -> 0.43367831
A18: Bátonyterenyei járás | B18: 117 | C18: =VLOOKUP(CONCATENATE("2001",'2001_60'!A18),aktivnepesseg!$C$2:$D$2226,2,FALSE) -> 13773 | D18: =SUM(F18:T18) -> 8923 | E18: =C18-D18 -> 4850 | F18: 667 | G18: 425 | H18: 631 | I18: 754 | J18: 1268 | K18: 852 | L18: 739 | M18: 554 | N18: 522 | O18: 489 | P18: 1230 | Q18: 405 | R18: 166 | S18: 206 | T18: 15 | U18: =E18*E$5 -> 4850 | V18: =F18*F$5 -> 600.3 | W18: =G18*G$5 -> 297.5 | X18: =H18*H$5 -> 315.5 | Y18: =I18*I$5 -> 226.2 | Z18: =J18*J$5 -> 126.8 | AA18: =SUM(U18:Z18)/$C18 -> 0.46586074 | AB18: =E18*E$6 -> 4850 | AC18: =F18*F$6 -> 583.625 | AD18: =G18*G$6 -> 265.625 | AE18: =H18*H$6 -> 236.625 | AF18: =I18*I$6 -> 94.25 | AG18: =SUM(AB18:AF18)/$C18 -> 0.43782219
A19: Békéscsabai járás | B19: 46 | C19: =VLOOKUP(CONCATENATE("2001",'2001_60'!A19),aktivnepesseg!$C$2:$D$2226,2,FALSE) -> 53185 | D19: =SUM(F19:T19) -> 41648 | E19: =C19-D19 -> 11537 | F19: 3525 | G19: 1452 | H19: 2491 | I19: 2757 | J19: 6159 | K19: 4008 | L19: 3324 | M19: 2734 | N19: 2195 | O19: 1936 | P19: 5685 | Q19: 2409 | R19: 1096 | S19: 1546 | T19: 331 | U19: =E19*E$5 -> 11537 | V19: =F19*F$5 -> 3172.5 | W19: =G19*G$5 -> 1016.4 | X19: =H19*H$5 -> 1245.5 | Y19: =I19*I$5 -> 827.1 | Z19: =J19*J$5 -> 615.9 | AA19: =SUM(U19:Z19)/$C19 -> 0.34623296 | AB19: =E19*E$6 -> 11537 | AC19: =F19*F$6 -> 3084.375 | AD19: =G19*G$6 -> 907.5 | AE19: =H19*H$6 -> 934.125 | AF19: =I19*I$6 -> 344.625 | AG19: =SUM(AB19:AF19)/$C19 -> 0.3160219
... A204: Zirci járás | B204: 192 | C204: =VLOOKUP(CONCATENATE("2001",'2001_60'!A204),aktivnepesseg!$C$2:$D$2226,2,FALSE) -> 11650 | D204: =SUM(F204:T204) -> 9578 | E204: =C204-D204 -> 2072 | F204: 661 | G204: 288 | H204: 438 | I204: 479 | J204: 1195 | K204: 860 | L204: 747 | M204: 731 | N204: 679 | O204: 676 | P204: 1851 | Q204: 528 | R204: 207 | S204: 212 | T204: 26 | U204: =E204*E$5 -> 2072 | V204: =F204*F$5 -> 594.9 | W204: =G204*G$5 -> 201.6 | X204: =H204*H$5 -> 219 | Y204: =I204*I$5 -> 143.7 | Z204: =J204*J$5 -> 119.5 | AA204: =SUM(U204:Z204)/$C204 -> 0.28761373 | AB204: =E204*E$6 -> 2072 | AC204: =F204*F$6 -> 578.375 | AD204: =G204*G$6 -> 180 | AE204: =H204*H$6 -> 164.25 | AF204: =I204*I$6 -> 59.875 | AG204: =SUM(AB204:AF204)/$C204 -> 0.26218884
A205: MAGYARORSZÁG totál | C205: =SUM(C8:C204) -> 5887316 | D205: =SUM(D8:D204) -> 4343234 | E205: =SUM(E8:E204) -> 1544082 | F205: =SUM(F8:F204) -> 313295 | G205: =SUM(G8:G204) -> 146090 | H205: =SUM(H8:H204) -> 234358 | I205: =SUM(I8:I204) -> 259141 | J205: =SUM(J8:J204) -> 658489 | ... T205: =SUM(T8:T204) -> 57360 | U205: =E205*E$5 -> 1544082 | V205: =F205*F$5 -> 281965.5 | W205: =G205*G$5 -> 102263 | X205: =H205*H$5 -> 117179 | Y205: =I205*I$5 -> 77742.3 | Z205: =J205*J$5 -> 65848.9 | AA205: =SUM(U205:Z205)/$C205 -> 0.37183 | AB205: =E205*E$6 -> 1544082 | AC205: =F205*F$6 -> 274133.12 | AD205: =G205*G$6 -> 91306.25 | AE205: =H205*H$6 -> 87884.25 | AF205: =I205*I$6 -> 32392.625 | AG205: =SUM(AB205:AF205)/$C205 -> 0.34477481
A207: Budapest | B207: 999 | C207: =VLOOKUP(CONCATENATE("2001",'2001_60'!A207),aktivnepesseg!$C$2:$D$2226,2,FALSE) -> 1052425 | D207: =SUM(F207:T207) -> 796528 | E207: =C207-D207 -> 255897 | F207: 47706 | G207: 21352 | H207: 31814 | I207: 33664 | J207: 116987 | K207: 51289 | L207: 37884 | M207: 37935 | N207: 34578 | O207: 34207 | P207: 127850 | Q207: 75054 | R207: 43218 | S207: 73345 | T207: 29645 | U207: =E207*E$5 -> 255897 | V207: =F207*F$5 -> 42935.4 | W207: =G207*G$5 -> 14946.4 | X207: =H207*H$5 -> 15907 | Y207: =I207*I$5 -> 10099.2 | Z207: =J207*J$5 -> 11698.7 | AA207: =SUM(U207:Z207)/$C207 -> 0.33397506 | AB207: =E207*E$6 -> 255897 | AC207: =F207*F$6 -> 41742.75 | AD207: =G207*G$6 -> 13345 | AE207: =H207*H$6 -> 11930.25 | AF207: =I207*I$6 -> 4208 | AG207: =SUM(AB207:AF207)/$C207 -> 0.31082785
A208: Mo N | C208: =SUM(C8:C204) -> 5887316 | D208: =SUM(D8:D204) -> 4343234 | E208: =SUM(E8:E204) -> 1544082 | F208: =SUM(F8:F204) -> 313295 | G208: =SUM(G8:G204) -> 146090 | H208: =SUM(H8:H204) -> 234358 | I208: =SUM(I8:I204) -> 259141 | J208: =SUM(J8:J204) -> 658489 | ... T208: =SUM(T8:T204) -> 57360
A209: Mo arány (adózókból) | F209: =F208/$D$208 -> 0.072134037 | G209: =G208/$D$208 -> 0.033636226 | H209: =H208/$D$208 -> 0.053959331 | I209: =I208/$D$208 -> 0.059665447 | J209: =J208/$D$208 -> 0.1516126 | K209: =K208/$D$208 -> 0.087139675 | L209: =L208/$D$208 -> 0.06594487 | M209: =M208/$D$208 -> 0.060783048 | ... T209: =T208/$D$208 -> 0.013206749
A210: Mo kum arány (adózókból) | F210: =F209 -> 0.072134037 | G210: =G209+F210 -> 0.10577026 | H210: =H209+G210 -> 0.15972959 | I210: =I209+H210 -> 0.21939504 | J210: =J209+I210 -> 0.37100764 | K210: =K209+J210 -> 0.45814732 | L210: =L209+K210 -> 0.52409219 | M210: =M209+L210 -> 0.58487523 | N210: =N209+M210 -> 0.63835543 | ... T210: =T209+S210 -> 1
A211: Mo arány (aktív korúakból) | D211: =D208/$C$208 -> 0.73772734 | E211: =E205/$C$205 -> 0.26227266 | F211: =F205/$C$205 -> 0.053215251 | G211: =G205/$C$205 -> 0.024814364 | H211: =H205/$C$205 -> 0.039807274 | I211: =I205/$C$205 -> 0.044016832 | J211: =J205/$C$205 -> 0.11184876 | K211: =K205/$C$205 -> 0.064285321 | L211: =L205/$C$205 -> 0.048649334 | ... T211: =T205/$C$205 -> 0.0097429797
A212: Mo kum arány (aktív korúakból) | E212: =E211 -> 0.26227266 | F212: =F211+E212 -> 0.31548791 | G212: =G211+F212 -> 0.34030227 | H212: =H211+G212 -> 0.38010954 | I212: =I211+H212 -> 0.42412638 | J212: =J211+I212 -> 0.53597514 | K212: =K211+J212 -> 0.60026046 | L212: =L211+K212 -> 0.64890979 | M212: =M211+L212 -> 0.69375111 | ... T212: =T211+S212 -> 1
A213: mediánjöv számítás adózók eltérés | K213: =600*(ABS(0.5-K210)/(ABS(0.5-K210)+ABS(0.5-L210))+700*ABS(0.5-L210)/(ABS(0.5-K210)+ABS(0.5-L210))) -> 153822.88
A214: mediánjöv számítás aktív korúak
A215: medián_atlag_jövedelem.xlsx

Sheet 2011_60
A1: KÜSZÖB | D1: Adósáv alja | E1: 0 | F1: 0 | G1: =F2 -> 300 | H1: =G2 -> 600 | I1: =H2 -> 800 | J1: =I2 -> 1000 | K1: =J2 -> 1200 | L1: =K2 -> 1500 | M1: =L2 -> 1800 | N1: =M2 -> 2000 | ... T1: =S2 -> 20000 | U1: V03 - alacsonyabb küszöb | AA1: median60esmedian70
A2: 1200 | D2: Adósáv teteje | E2: 0 | F2: 300 | G2: 600 | H2: 800 | I2: 1000 | J2: 1200 | K2: 1500 | L2: 1800 | M2: 2000 | N2: 2500 | O2: 3000 | P2: 4000 | Q2: 5000 | R2: 10000 | S2: 20000 | U2: AKTÍV KORÚAKHOZ
A3: 1000 | D3: Adósáv közepe | E3: 0 | F3: =AVERAGE(F1:F2) -> 150 | G3: =AVERAGE(G1:G2) -> 450 | H3: =AVERAGE(H1:H2) -> 700 | I3: =AVERAGE(I1:I2) -> 900 | J3: =AVERAGE(J1:J2) -> 1100 | K3: =AVERAGE(K1:K2) -> 1350 | L3: =AVERAGE(L1:L2) -> 1650 | M3: =AVERAGE(M1:M2) -> 1900 | ... S3: =AVERAGE(S1:S2) -> 15000 | U3: 1 | V3: 1 | W3: 1 | X3: 1 | Y3: 1
A4: 800 | D4: szorzóP1v0102 | E4: =($A$2-E3)/$A$2 -> 1 | F4: =($A$2-F3)/$A$2 -> 0.875 | G4: =($A$2-G3)/$A$2 -> 0.625 | H4: =($A$2-H3)/$A$2 -> 0.41666667 | I4: =($A$2-I3)/$A$2 -> 0.25 | J4: =($A$2-J3)/$A$2 -> 0.083333333 | V4: P1 részeredmények
A5: a szürkével jelöltek alternatív küszöbértékek | D5: szorzóP1v03 | E5: =($A$3-E3)/$A$3 -> 1 | F5: =($A$3-F3)/$A$3 -> 0.85 | G5: =($A$3-G3)/$A$3 -> 0.55 | H5: =($A$3-H3)/$A$3 -> 0.3 | I5: =($A$3-I3)/$A$3 -> 0.1
D6: szorzóP1median60es70 | E6: 1 | F6: =($A$4-F3)/$A$4 -> 0.8125 | G6: =($A$4-G3)/$A$4 -> 0.4375 | H6: =($A$4-H3)/$A$4 -> 0.125
B7: kod | C7: aktivkoru | D7: összes adózó | E7: NULLA sávon adózó aktív korú | F7: 2011 SZJA adófizető; 0-300 000 Ft éves összevont adóalapba tartozó jövedelmi sávon (fő) | G7: 2011 SZJA adófizető; 300 001-600 000 Ft éves összevont adóalapba tartozó jövedelmi sávon (fő) | H7: 2011 SZJA adófizető; 600 001-800 000 Ft éves összevont adóalapba tartozó jövedelmi sávon (fő) | I7: 2011 SZJA adófizető; 800 001-1 000 000 Ft éves összevont adóalapba tartozó jövedelmi sávon (fő) | J7: 2011 SZJA adófizető; 1 000 001-1 200 000 Ft éves összevont adóalapba tartozó jövedelmi sávon (fő) | K7: 2011 SZJA adófizető; 1 200 001-1 500 000 Ft éves összevont adóalapba tartozó jövedelmi sávon (fő) | L7: 2011 SZJA adófizető; 1 500 001-1 800 000 Ft éves összevont adóalapba tartozó jövedelmi sávon (fő) | M7: 2011 SZJA adófizető; 1 800 001-2 000 000 Ft éves összevont adóalapba tartozó jövedelmi sávon (fő) | N7: 2011 SZJA adófizető; 2 000 001-2 500 000 Ft éves összevont adóalapba tartozó jövedelmi sávon (fő) | O7: 2011 SZJA adófizető; 2 500 001-3 000 000 Ft éves összevont adóalapba tartozó jövedelmi sávon (fő) | P7: 2011 SZJA adófizető; 3 000 001-4 000 000 Ft éves összevont adóalapba tartozó jövedelmi sávon (fő) | Q7: 2011 SZJA adófizető; 4 000 001-5 000 000 Ft éves összevont adóalapba tartozó jövedelmi sávon (fő) | R7: 2011 SZJA adófizető; 5 000 001-10 000 000 Ft éves összevont adóalapba tartozó jövedelmi sávon (fő) | S7: 2011 SZJA adófizető; 10 000 001-20 000 000 Ft éves összevont adóalapba tartozó jövedelmi sávon (fő) | T7: 2011 SZJA adófizető; 20 000 000-X Ft éves összevont adóalapba tartozó jövedelmi sávon (fő) | U7: 0-0 sáv (új jöv sáv!) | V7: 0-300 | W7: 300-600 | X7: 600-800 | Y7: 800-1000 | Z7: P1 | AA7: 0-0 sáv (új jöv sáv!) | AB7: 0-300 | AC7: 300-600 | AD7: 600-800 | AE7: P1
A8: Ajkai járás | B8: 183 | C8: =VLOOKUP(CONCATENATE("2011",'2011_60'!A8),aktivnepesseg!$C$2:$D$2226,2,FALSE) -> 24208 | D8: =SUM(F8:T8) -> 19847 | E8: =C8-D8 -> 4361 | F8: 2855 | G8: 1437 | H8: 937 | I8: 1477 | J8: 2452 | K8: 2894 | L8: 1949 | M8: 972 | N8: 1704 | O8: 1024 | P8: 1075 | Q8: 485 | R8: 510 | S8: 69 | T8: 7 | U8: =E8*E$5 -> 4361 | V8: =F8*F$5 -> 2426.75 | W8: =G8*G$5 -> 790.35 | X8: =H8*H$5 -> 281.1 | Y8: =I8*I$5 -> 147.7 | Z8: =SUM(U8:Y8)/$C8 -> 0.3307543 | AA8: =E8*E$6 -> 4361 | AB8: =F8*F$6 -> 2319.6875 | AC8: =G8*G$6 -> 628.6875 | AD8: =H8*H$6 -> 117.125 | AE8: =SUM(AA8:AD8)/$C8 -> 0.30677875
A9: Aszódi járás | B9: 122 | C9: =VLOOKUP(CONCATENATE("2011",'2011_60'!A9),aktivnepesseg!$C$2:$D$2226,2,FALSE) -> 22888 | D9: =SUM(F9:T9) -> 16467 | E9: =C9-D9 -> 6421 | F9: 2130 | G9: 1535 | H9: 936 | I9: 1395 | J9: 1802 | K9: 1549 | L9: 1522 | M9: 846 | N9: 1494 | O9: 1046 | P9: 1095 | Q9: 481 | R9: 556 | S9: 76 | T9: 4 | U9: =E9*E$5 -> 6421 | V9: =F9*F$5 -> 1810.5 | W9: =G9*G$5 -> 844.25 | X9: =H9*H$5 -> 280.8 | Y9: =I9*I$5 -> 139.5 | Z9: =SUM(U9:Y9)/$C9 -> 0.41489208 | AA9: =E9*E$6 -> 6421 | AB9: =F9*F$6 -> 1730.625 | AC9: =G9*G$6 -> 671.5625 | AD9: =H9*H$6 -> 117 | AE9: =SUM(AA9:AD9)/$C9 -> 0.39060589
A10: Bácsalmási járás | B10: 34 | C10: =VLOOKUP(CONCATENATE("2011",'2011_60'!A10),aktivnepesseg!$C$2:$D$2226,2,FALSE) -> 11576 | D10: =SUM(F10:T10) -> 8095 | E10: =C10-D10 -> 3481 | F10: 2125 | G10: 965 | H10: 466 | I10: 671 | J10: 915 | K10: 823 | L10: 599 | M10: 310 | N10: 547 | O10: 256 | P10: 258 | Q10: 87 | R10: 69 | S10: 4 | T10: 0 | U10: =E10*E$5 -> 3481 | V10: =F10*F$5 -> 1806.25 | W10: =G10*G$5 -> 530.75 | X10: =H10*H$5 -> 139.8 | Y10: =I10*I$5 -> 67.1 | Z10: =SUM(U10:Y10)/$C10 -> 0.52046475 | AA10: =E10*E$6 -> 3481 | AB10: =F10*F$6 -> 1726.5625 | AC10: =G10*G$6 -> 422.1875 | AD10: =H10*H$6 -> 58.25 | AE10: =SUM(AA10:AD10)/$C10 -> 0.49136144
A11: Bajai járás | B11: 35 | C11: =VLOOKUP(CONCATENATE("2011",'2011_60'!A11),aktivnepesseg!$C$2:$D$2226,2,FALSE) -> 39338 | D11: =SUM(F11:T11) -> 28114 | E11: =C11-D11 -> 11224 | F11: 6121 | G11: 3158 | H11: 1651 | I11: 2480 | J11: 3325 | K11: 2476 | L11: 2124 | M11: 1149 | N11: 1980 | O11: 1137 | P11: 1282 | Q11: 544 | R11: 607 | S11: 64 | T11: 16 | U11: =E11*E$5 -> 11224 | V11: =F11*F$5 -> 5202.85 | W11: =G11*G$5 -> 1736.9 | X11: =H11*H$5 -> 495.3 | Y11: =I11*I$5 -> 248 | Z11: =SUM(U11:Y11)/$C11 -> 0.48063069 | AA11: =E11*E$6 -> 11224 | AB11: =F11*F$6 -> 4973.3125 | AC11: =G11*G$6 -> 1381.625 | AD11: =H11*H$6 -> 206.375 | AE11: =SUM(AA11:AD11)/$C11 -> 0.45211532
A12: Baktalórántházai járás | B12: 148 | C12: =VLOOKUP(CONCATENATE("2011",'2011_60'!A12),aktivnepesseg!$C$2:$D$2226,2,FALSE) -> 11561 | D12: =SUM(F12:T12) -> 7803 | E12: =C12-D12 -> 3758 | F12: 1701 | G12: 1098 | H12: 677 | I12: 878 | J12: 1022 | K12: 703 | L12: 450 | M12: 224 | N12: 428 | O12: 243 | P12: 235 | Q12: 82 | R12: 55 | S12: 7 | T12: 0 | U12: =E12*E$5 -> 3758 | V12: =F12*F$5 -> 1445.85 | W12: =G12*G$5 -> 603.9 | X12: =H12*H$5 -> 203.1 | Y12: =I12*I$5 -> 87.8 | Z12: =SUM(U12:Y12)/$C12 -> 0.52751925 | AA12: =E12*E$6 -> 3758 | AB12: =F12*F$6 -> 1382.0625 | AC12: =G12*G$6 -> 480.375 | AD12: =H12*H$6 -> 84.625 | AE12: =SUM(AA12:AD12)/$C12 -> 0.49347483
A13: Balassagyarmati járás | B13: 116 | C13: =VLOOKUP(CONCATENATE("2011",'2011_60'!A13),aktivnepesseg!$C$2:$D$2226,2,FALSE) -> 24482 | D13: =SUM(F13:T13) -> 18000 | E13: =C13-D13 -> 6482 | F13: 2901 | G13: 1718 | H13: 972 | I13: 1423 | J13: 1927 | K13: 1926 | L13: 1545 | M13: 1033 | N13: 1678 | O13: 941 | P13: 975 | Q13: 450 | R13: 460 | S13: 51 | T13: 0 | U13: =E13*E$5 -> 6482 | V13: =F13*F$5 -> 2465.85 | W13: =G13*G$5 -> 944.9 | X13: =H13*H$5 -> 291.6 | Y13: =I13*I$5 -> 142.3 | Z13: =SUM(U13:Y13)/$C13 -> 0.42180582 | AA13: =E13*E$6 -> 6482 | AB13: =F13*F$6 -> 2357.0625 | AC13: =G13*G$6 -> 751.625 | AD13: =H13*H$6 -> 121.5 | AE13: =SUM(AA13:AD13)/$C13 -> 0.39670727
A14: Balatonalmádi járás | B14: 184 | C14: =VLOOKUP(CONCATENATE("2011",'2011_60'!A14),aktivnepesseg!$C$2:$D$2226,2,FALSE) -> 14302 | D14: =SUM(F14:T14) -> 12033 | E14: =C14-D14 -> 2269 | F14: 2087 | G14: 1222 | H14: 677 | I14: 979 | J14: 1412 | K14: 1299 | L14: 906 | M14: 471 | N14: 884 | O14: 592 | P14: 643 | Q14: 303 | R14: 444 | S14: 85 | T14: 29 | U14: =E14*E$5 -> 2269 | V14: =F14*F$5 -> 1773.95 | W14: =G14*G$5 -> 672.1 | X14: =H14*H$5 -> 203.1 | Y14: =I14*I$5 -> 97.9 | Z14: =SUM(U14:Y14)/$C14 -> 0.35072368 | AA14: =E14*E$6 -> 2269 | AB14: =F14*F$6 -> 1695.6875 | AC14: =G14*G$6 -> 534.625 | AD14: =H14*H$6 -> 84.625 | AE14: =SUM(AA14:AD14)/$C14 -> 0.32051024
A15: Balatonfüredi járás | B15: 185 | C15: =VLOOKUP(CONCATENATE("2011",'2011_60'!A15),aktivnepesseg!$C$2:$D$2226,2,FALSE) -> 14150 | D15: =SUM(F15:T15) -> 12519 | E15: =C15-D15 -> 1631 | F15: 2635 | G15: 1286 | H15: 800 | I15: 1005 | J15: 1434 | K15: 1191 | L15: 895 | M15: 476 | N15: 862 | O15: 505 | P15: 587 | Q15: 328 | R15: 406 | S15: 87 | T15: 22 | U15: =E15*E$5 -> 1631 | V15: =F15*F$5 -> 2239.75 | W15: =G15*G$5 -> 707.3 | X15: =H15*H$5 -> 240 | Y15: =I15*I$5 -> 100.5 | Z15: =SUM(U15:Y15)/$C15 -> 0.34760071 | AA15: =E15*E$6 -> 1631 | AB15: =F15*F$6 -> 2140.9375 | AC15: =G15*G$6 -> 562.625 | AD15: =H15*H$6 -> 100 | AE15: =SUM(AA15:AD15)/$C15 -> 0.31339664
A16: Balmazújvárosi járás | B16: 93 | C16: =VLOOKUP(CONCATENATE("2011",'2011_60'!A16),aktivnepesseg!$C$2:$D$2226,2,FALSE) -> 17841 | D16: =SUM(F16:T16) -> 13180 | E16: =C16-D16 -> 4661 | F16: 2593 | G16: 1527 | H16: 981 | I16: 1308 | J16: 1699 | K16: 1454 | L16: 1072 | M16: 543 | N16: 839 | O16: 447 | P16: 415 | Q16: 143 | R16: 148 | S16: 11 | T16: 0 | U16: =E16*E$5 -> 4661 | V16: =F16*F$5 -> 2204.05 | W16: =G16*G$5 -> 839.85 | X16: =H16*H$5 -> 294.3 | Y16: =I16*I$5 -> 130.8 | Z16: =SUM(U16:Y16)/$C16 -> 0.45569195 | AA16: =E16*E$6 -> 4661 | AB16: =F16*F$6 -> 2106.8125 | AC16: =G16*G$6 -> 668.0625 | AD16: =H16*H$6 -> 122.625 | AE16: =SUM(AA16:AD16)/$C16 -> 0.42365899
A17: Barcsi járás | B17: 140 | C17: =VLOOKUP(CONCATENATE("2011",'2011_60'!A17),aktivnepesseg!$C$2:$D$2226,2,FALSE) -> 14263 | D17: =SUM(F17:T17) -> 9744 | E17: =C17-D17 -> 4519 | F17: 2238 | G17: 1051 | H17: 609 | I17: 831 | J17: 1122 | K17: 997 | L17: 841 | M17: 410 | N17: 638 | O17: 300 | P17: 433 | Q17: 144 | R17: 120 | S17: 10 | T17: 0 | U17: =E17*E$5 -> 4519 | V17: =F17*F$5 -> 1902.3 | W17: =G17*G$5 -> 578.05 | X17: =H17*H$5 -> 182.7 | Y17: =I17*I$5 -> 83.1 | Z17: =SUM(U17:Y17)/$C17 -> 0.5093704 | AA17: =E17*E$6 -> 4519 | AB17: =F17*F$6 -> 1818.375 | AC17: =G17*G$6 -> 459.8125 | AD17: =H17*H$6 -> 76.125 | AE17: =SUM(AA17:AD17)/$C17 -> 0.48189809
A18: Bátonyterenyei járás | B18: 117 | C18: =VLOOKUP(CONCATENATE("2011",'2011_60'!A18),aktivnepesseg!$C$2:$D$2226,2,FALSE) -> 12862 | D18: =SUM(F18:T18) -> 9057 | E18: =C18-D18 -> 3805 | F18: 1696 | G18: 929 | H18: 553 | I18: 766 | J18: 976 | K18: 1042 | L18: 712 | M18: 409 | N18: 676 | O18: 409 | P18: 479 | Q18: 207 | R18: 191 | S18: 12 | T18: 0 | U18: =E18*E$5 -> 3805 | V18: =F18*F$5 -> 1441.6 | W18: =G18*G$5 -> 510.95 | X18: =H18*H$5 -> 165.9 | Y18: =I18*I$5 -> 76.6 | Z18: =SUM(U18:Y18)/$C18 -> 0.46649432 | AA18: =E18*E$6 -> 3805 | AB18: =F18*F$6 -> 1378 | AC18: =G18*G$6 -> 406.4375 | AD18: =H18*H$6 -> 69.125 | AE18: =SUM(AA18:AD18)/$C18 -> 0.43994422
A19: Békéscsabai járás | B19: 46 | C19: =VLOOKUP(CONCATENATE("2011",'2011_60'!A19),aktivnepesseg!$C$2:$D$2226,2,FALSE) -> 50213 | D19: =SUM(F19:T19) -> 38684 | E19: =C19-D19 -> 11529 | F19: 7136 | G19: 3746 | H19: 2111 | I19: 2851 | J19: 4273 | K19: 3849 | L19: 3183 | M19: 1799 | N19: 3184 | O19: 1871 | P19: 2187 | Q19: 1148 | R19: 1167 | S19: 158 | T19: 21 | U19: =E19*E$5 -> 11529 | V19: =F19*F$5 -> 6065.6 | W19: =G19*G$5 -> 2060.3 | X19: =H19*H$5 -> 633.3 | Y19: =I19*I$5 -> 285.1 | Z19: =SUM(U19:Y19)/$C19 -> 0.40972059 | AA19: =E19*E$6 -> 11529 | AB19: =F19*F$6 -> 5798 | AC19: =G19*G$6 -> 1638.875 | AD19: =H19*H$6 -> 263.875 | AE19: =SUM(AA19:AD19)/$C19 -> 0.38296358
... A204: Zirci járás | B204: 192 | C204: =VLOOKUP(CONCATENATE("2011",'2011_60'!A204),aktivnepesseg!$C$2:$D$2226,2,FALSE) -> 11949 | D204: =SUM(F204:T204) -> 9443 | E204: =C204-D204 -> 2506 | F204: 1267 | G204: 748 | H204: 516 | I204: 763 | J204: 1101 | K204: 1135 | L204: 1033 | M204: 635 | N204: 882 | O204: 492 | P204: 450 | Q204: 208 | R204: 185 | S204: 28 | T204: 0 | U204: =E204*E$5 -> 2506 | V204: =F204*F$5 -> 1076.95 | W204: =G204*G$5 -> 411.4 | X204: =H204*H$5 -> 154.8 | Y204: =I204*I$5 -> 76.3 | Z204: =SUM(U204:Y204)/$C204 -> 0.35362373 | AA204: =E204*E$6 -> 2506 | AB204: =F204*F$6 -> 1029.4375 | AC204: =G204*G$6 -> 327.25 | AD204: =H204*H$6 -> 64.5 | AE204: =SUM(AA204:AD204)/$C204 -> 0.32866244
A205: MAGYARORSZÁG totál | C205: =SUM(C8:C204) -> 6064308 | D205: =SUM(D8:D204) -> 4386263 | E205: =SUM(E8:E204) -> 1678045 | F205: =SUM(F8:F204) -> 731134 | G205: =SUM(G8:G204) -> 404018 | H205: =SUM(H8:H204) -> 236126 | I205: =SUM(I8:I204) -> 346884 | J205: =SUM(J8:J204) -> 470569 | ... T205: =SUM(T8:T204) -> 8737 | U205: =E205*E$5 -> 1678045 | V205: =F205*F$5 -> 621463.9 | W205: =G205*G$5 -> 222209.9 | X205: =H205*H$5 -> 70837.8 | Y205: =I205*I$5 -> 34688.4 | Z205: =SUM(U205:Y205)/$C205 -> 0.4332308 | AA205: =E205*E$6 -> 1678045 | AB205: =F205*F$6 -> 594046.38 | AC205: =G205*G$6 -> 176757.88 | AD205: =H205*H$6 -> 29515.75 | AE205: =SUM(AA205:AD205)/$C205 -> 0.40868059
A207: Budapest | B207: 999 | C207: =VLOOKUP(CONCATENATE("2011",'2011_60'!A207),aktivnepesseg!$C$2:$D$2226,2,FALSE) -> 1076676 | D207: =SUM(F207:T207) -> 730400 | E207: =C207-D207 -> 346276 | F207: 95271 | G207: 60740 | H207: 32762 | I207: 54885 | J207: 66604 | K207: 58838 | L207: 55387 | M207: 30055 | N207: 56149 | O207: 42237 | P207: 61190 | Q207: 35766 | R207: 58697 | S207: 17154 | T207: 4665 | U207: =E207*E$5 -> 346276 | V207: =F207*F$5 -> 80980.35 | W207: =G207*G$5 -> 33407 | X207: =H207*H$5 -> 9828.6 | Y207: =I207*I$5 -> 5488.5 | Z207: =SUM(U207:Y207)/$C207 -> 0.44208327 | AA207: =E207*E$6 -> 346276 | AB207: =F207*F$6 -> 77407.688 | AC207: =G207*G$6 -> 26573.75 | AD207: =H207*H$6 -> 4095.25 | AE207: =SUM(AA207:AD207)/$C207 -> 0.42199574
A208: Mo N | D208: =SUM(D8:D204) -> 4386263 | F208: =SUM(F8:F204) -> 731134 | G208: =SUM(G8:G204) -> 404018 | H208: =SUM(H8:H204) -> 236126 | I208: =SUM(I8:I204) -> 346884 | J208: =SUM(J8:J204) -> 470569 | K208: =SUM(K8:K204) -> 438738 | L208: =SUM(L8:L204) -> 360601 | M208: =SUM(M8:M204) -> 193815 | ... T208: =SUM(T8:T204) -> 8737
A209: Mo arány (adózókból) | F209: =F208/$D$208 -> 0.16668722 | G209: =G208/$D$208 -> 0.092109844 | H209: =H208/$D$208 -> 0.053833069 | I209: =I208/$D$208 -> 0.079084177 | J209: =J208/$D$208 -> 0.10728244 | K209: =K208/$D$208 -> 0.10002547 | L209: =L208/$D$208 -> 0.082211441 | M209: =M208/$D$208 -> 0.044186817 | ... T209: =T208/$D$208 -> 0.0019919006
A210: Mo kum arány (adózókból) | F210: =F209 -> 0.16668722 | G210: =G209+F210 -> 0.25879707 | H210: =H209+G210 -> 0.31263014 | I210: =I209+H210 -> 0.39171431 | J210: =J209+I210 -> 0.49899675 | K210: =K209+J210 -> 0.59902222 | L210: =L209+K210 -> 0.68123366 | M210: =M209+L210 -> 0.72542048 | N210: =N209+M210 -> 0.80480126 | ... T210: =T209+S210 -> 1
A211: Mo arány (aktív korúakból) | D211: =D205/$C$205 -> 0.72329159 | E211: =E205/$C$205 -> 0.27670841 | F211: =F205/$C$205 -> 0.12056347 | G211: =G205/$C$205 -> 0.066622276 | H211: =H205/$C$205 -> 0.038937006 | I211: =I205/$C$205 -> 0.057200921 | J211: =J205/$C$205 -> 0.077596488 | K211: =K205/$C$205 -> 0.072347579 | ... T211: =T205/$C$205 -> 0.001440725
A212: Mo kum arány (aktív korúakból) | E212: =E211 -> 0.27670841 | F212: =F211+E212 -> 0.39727187 | G212: =G211+F212 -> 0.46389415 | H212: =H211+G212 -> 0.50283116 | I212: =I211+H212 -> 0.56003208 | J212: =J211+I212 -> 0.63762856 | K212: =K211+J212 -> 0.70997614 | L212: =L211+K212 -> 0.76943899 | M212: =M211+L212 -> 0.80139894 | ... T212: =T211+S212 -> 1

Sheet 2022_60
A1: KÜSZÖB | D1: Adósáv alja | E1: 0 | F1: 0 | G1: 300 | H1: 600 | I1: 800 | J1: 1000 | K1: 1200 | L1: 1500 | M1: 1800 | N1: 2000 | O1: 2500 | P1: 3000 | Q1: 4000 | R1: 5000 | S1: V03 - alacsonyabb küszöb
A2: 3000 | D2: Adósáv teteje | E2: 0 | F2: 300 | G2: 600 | H2: 800 | I2: 1000 | J2: 1200 | K2: 1500 | L2: 1800 | M2: 2000 | N2: 2500 | O2: 3000 | P2: 4000 | Q2: 5000 | R2: 10000 | S2: AKTÍV KORÚAKHOZ
A3: 2000 | D3: Adósáv közepe | E3: 0 | F3: 150 | G3: 450 | H3: 700 | I3: 900 | J3: 1100 | K3: 1350 | L3: 1650 | M3: 1900 | N3: 2250 | O3: 2750 | P3: 3500 | Q3: 4500 | R3: 7500 | S3: 1 | T3: 1 | U3: 1 | V3: 1 | W3: 1 | X3: 1 | Y3: 1 | Z3: 1 | AA3: 1
A4: a szürkével jelölt alternatív küszöbérték | D4: szorzóP1v0102 | E4: =($A$2-E3)/$A$2 -> 1 | F4: =($A$2-F3)/$A$2 -> 0.95 | G4: =($A$2-G3)/$A$2 -> 0.85 | H4: =($A$2-H3)/$A$2 -> 0.76666667 | I4: =($A$2-I3)/$A$2 -> 0.7 | J4: =($A$2-J3)/$A$2 -> 0.63333333 | K4: =($A$2-K3)/$A$2 -> 0.55 | L4: =($A$2-L3)/$A$2 -> 0.45 | ... R4: =($A$2-R3)/$A$2 -> -1.5 | S4: P1 részeredmények
D5: szorzóP1v03 | E5: =($A$3-E3)/$A$3 -> 1 | F5: =($A$3-F3)/$A$3 -> 0.925 | G5: =($A$3-G3)/$A$3 -> 0.775 | H5: =($A$3-H3)/$A$3 -> 0.65 | I5: =($A$3-I3)/$A$3 -> 0.55 | J5: =($A$3-J3)/$A$3 -> 0.45 | K5: =($A$3-K3)/$A$3 -> 0.325 | L5: =($A$3-L3)/$A$3 -> 0.175 | M5: =($A$3-M3)/$A$3 -> 0.05
B6: kod | C6: aktivkoru | D6: 2022 SZJA adófizető; Összesen (fő) | E6: NULLA sávon adózó aktív korú | F6: 2022 SZJA adófizető; 0-300 000 Ft éves összevont adóalapba tartozó jövedelmi sávon (fő) | G6: 2022 SZJA adófizető; 300 001-600 000 Ft éves összevont adóalapba tartozó jövedelmi sávon (fő) | H6: 2022 SZJA adófizető; 600 001-800 000 Ft éves összevont adóalapba tartozó jövedelmi sávon (fő) | I6: 2022 SZJA adófizető; 800 001-1 000 000 Ft éves összevont adóalapba tartozó jövedelmi sávon (fő) | J6: 2022 SZJA adófizető; 1 000 001-1 200 000 Ft éves összevont adóalapba tartozó jövedelmi sávon (fő) | K6: 2022 SZJA adófizető; 1 200 001-1 500 000 Ft éves összevont adóalapba tartozó jövedelmi sávon (fő) | L6: 2022 SZJA adófizető; 1 500 001-1 800 000 Ft éves összevont adóalapba tartozó jövedelmi sávon (fő) | M6: 2022 SZJA adófizető; 1 800 001-2 000 000 Ft éves összevont adóalapba tartozó jövedelmi sávon (fő) | N6: 2022 SZJA adófizető; 2 000 001-2 500 000 Ft éves összevont adóalapba tartozó jövedelmi sávon (fő) | O6: 2022 SZJA adófizető; 2 500 001-3 000 000 Ft éves összevont adóalapba tartozó jövedelmi sávon (fő) | P6: 2022 SZJA adófizető; 3 000 001-4 000 000 Ft éves összevont adóalapba tartozó jövedelmi sávon (fő) | Q6: 2022 SZJA adófizető; 4 000 001-5 000 000 Ft éves összevont adóalapba tartozó jövedelmi sávon (fő) | R6: 2022 SZJA adófizető; 5 000 000-X Ft éves összevont adóalapba tartozó jövedelmi sávon (fő) | S6: 0-0 sáv (új jöv sáv!) | T6: 0-300 | U6: 300-600 | V6: 600-800 | W6: 800-1000 | X6: 1000-1200 | Y6: 1200-1500 | Z6: 1500-1800 | AA6: 1800-2000 | AB6: P1
A7: Ajkai járás | B7: 183 | C7: =VLOOKUP(CONCATENATE("2022",'2022_60'!A7),aktivnepesseg!$C$2:$D$2226,2,FALSE) -> 22842 | D7: 19784 | E7: =C7-D7 -> 3058 | F7: 2300 | G7: 657 | H7: 380 | I7: 318 | J7: 431 | K7: 422 | L7: 524 | M7: 289 | N7: 1036 | O7: 1103 | P7: 3619 | Q7: 2540 | R7: 6145 | S7: =E7*E$5 -> 3058 | T7: =F7*F$5 -> 2127.5 | U7: =G7*G$5 -> 509.175 | V7: =H7*H$5 -> 247 | W7: =I7*I$5 -> 174.9 | X7: =J7*J$5 -> 193.95 | Y7: =K7*K$5 -> 137.15 | Z7: =L7*L$5 -> 91.7 | AA7: =M7*M$5 -> 14.45 | AB7: =SUM(S7:AA7)/$C7 -> 0.28691993
A8: Aszódi járás | B8: 122 | C8: =VLOOKUP(CONCATENATE("2022",'2022_60'!A8),aktivnepesseg!$C$2:$D$2226,2,FALSE) -> 24391 | D8: 20139 | E8: =C8-D8 -> 4252 | F8: 2108 | G8: 786 | H8: 487 | I8: 380 | J8: 650 | K8: 511 | L8: 673 | M8: 330 | N8: 1262 | O8: 1055 | P8: 3110 | Q8: 2248 | R8: 6536 | S8: =E8*E$5 -> 4252 | T8: =F8*F$5 -> 1949.9 | U8: =G8*G$5 -> 609.15 | V8: =H8*H$5 -> 316.55 | W8: =I8*I$5 -> 209 | X8: =J8*J$5 -> 292.5 | Y8: =K8*K$5 -> 166.075 | Z8: =L8*L$5 -> 117.775 | AA8: =M8*M$5 -> 16.5 | AB8: =SUM(S8:AA8)/$C8 -> 0.32509737
A9: Bácsalmási járás | B9: 34 | C9: =VLOOKUP(CONCATENATE("2022",'2022_60'!A9),aktivnepesseg!$C$2:$D$2226,2,FALSE) -> 10675 | D9: 8671 | E9: =C9-D9 -> 2004 | F9: 1520 | G9: 413 | H9: 233 | I9: 198 | J9: 431 | K9: 316 | L9: 342 | M9: 140 | N9: 612 | O9: 500 | P9: 1528 | Q9: 938 | R9: 1487 | S9: =E9*E$5 -> 2004 | T9: =F9*F$5 -> 1406 | U9: =G9*G$5 -> 320.075 | V9: =H9*H$5 -> 151.45 | W9: =I9*I$5 -> 108.9 | X9: =J9*J$5 -> 193.95 | Y9: =K9*K$5 -> 102.7 | Z9: =L9*L$5 -> 59.85 | AA9: =M9*M$5 -> 7 | AB9: =SUM(S9:AA9)/$C9 -> 0.40786183
A10: Bajai járás | B10: 35 | C10: =VLOOKUP(CONCATENATE("2022",'2022_60'!A10),aktivnepesseg!$C$2:$D$2226,2,FALSE) -> 37088 | D10: 30128 | E10: =C10-D10 -> 6960 | F10: 4739 | G10: 1208 | H10: 771 | I10: 608 | J10: 1101 | K10: 784 | L10: 1023 | M10: 511 | N10: 2164 | O10: 1626 | P10: 5385 | Q10: 3029 | R10: 7161 | S10: =E10*E$5 -> 6960 | T10: =F10*F$5 -> 4383.575 | U10: =G10*G$5 -> 936.2 | V10: =H10*H$5 -> 501.15 | W10: =I10*I$5 -> 334.4 | X10: =J10*J$5 -> 495.45 | Y10: =K10*K$5 -> 254.8 | Z10: =L10*L$5 -> 179.025 | AA10: =M10*M$5 -> 25.55 | AB10: =SUM(S10:AA10)/$C10 -> 0.37937203
A11: Baktalórántházai járás | B11: 148 | C11: =VLOOKUP(CONCATENATE("2022",'2022_60'!A11),aktivnepesseg!$C$2:$D$2226,2,FALSE) -> 11459 | D11: 9469 | E11: =C11-D11 -> 1990 | F11: 1486 | G11: 481 | H11: 302 | I11: 280 | J11: 645 | K11: 334 | L11: 384 | M11: 160 | N11: 649 | O11: 500 | P11: 1620 | Q11: 1037 | R11: 1586 | S11: =E11*E$5 -> 1990 | T11: =F11*F$5 -> 1374.55 | U11: =G11*G$5 -> 372.775 | V11: =H11*H$5 -> 196.3 | W11: =I11*I$5 -> 154 | X11: =J11*J$5 -> 290.25 | Y11: =K11*K$5 -> 108.55 | Z11: =L11*L$5 -> 67.2 | AA11: =M11*M$5 -> 8 | AB11: =SUM(S11:AA11)/$C11 -> 0.39808229
A12: Balassagyarmati járás | B12: 116 | C12: =VLOOKUP(CONCATENATE("2022",'2022_60'!A12),aktivnepesseg!$C$2:$D$2226,2,FALSE) -> 22987 | D12: 19538 | E12: =C12-D12 -> 3449 | F12: 2483 | G12: 735 | H12: 448 | I12: 369 | J12: 633 | K12: 510 | L12: 502 | M12: 311 | N12: 1202 | O12: 995 | P12: 3078 | Q12: 2287 | R12: 5924 | S12: =E12*E$5 -> 3449 | T12: =F12*F$5 -> 2296.775 | U12: =G12*G$5 -> 569.625 | V12: =H12*H$5 -> 291.2 | W12: =I12*I$5 -> 202.95 | X12: =J12*J$5 -> 284.85 | Y12: =K12*K$5 -> 165.75 | Z12: =L12*L$5 -> 87.85 | AA12: =M12*M$5 -> 15.55 | AB12: =SUM(S12:AA12)/$C12 -> 0.32033541
A13: Balatonalmádi járás | B13: 184 | C13: =VLOOKUP(CONCATENATE("2022",'2022_60'!A13),aktivnepesseg!$C$2:$D$2226,2,FALSE) -> 15650 | D13: 14506 | E13: =C13-D13 -> 1144 | F13: 1985 | G13: 602 | H13: 366 | I13: 269 | J13: 356 | K13: 378 | L13: 398 | M13: 230 | N13: 823 | O13: 715 | P13: 2288 | Q13: 1564 | R13: 4527 | S13: =E13*E$5 -> 1144 | T13: =F13*F$5 -> 1836.125 | U13: =G13*G$5 -> 466.55 | V13: =H13*H$5 -> 237.9 | W13: =I13*I$5 -> 147.95 | X13: =J13*J$5 -> 160.2 | Y13: =K13*K$5 -> 122.85 | Z13: =L13*L$5 -> 69.65 | AA13: =M13*M$5 -> 11.5 | AB13: =SUM(S13:AA13)/$C13 -> 0.26816134
A14: Balatonfüredi járás | B14: 185 | C14: =VLOOKUP(CONCATENATE("2022",'2022_60'!A14),aktivnepesseg!$C$2:$D$2226,2,FALSE) -> 14676 | D14: 13929 | E14: =C14-D14 -> 747 | F14: 2443 | G14: 593 | H14: 338 | I14: 280 | J14: 386 | K14: 338 | L14: 410 | M14: 219 | N14: 699 | O14: 663 | P14: 2116 | Q14: 1397 | R14: 3981 | S14: =E14*E$5 -> 747 | T14: =F14*F$5 -> 2259.775 | U14: =G14*G$5 -> 459.575 | V14: =H14*H$5 -> 219.7 | W14: =I14*I$5 -> 154 | X14: =J14*J$5 -> 173.7 | Y14: =K14*K$5 -> 109.85 | Z14: =L14*L$5 -> 71.75 | AA14: =M14*M$5 -> 10.95 | AB14: =SUM(S14:AA14)/$C14 -> 0.28661079
A15: Balmazújvárosi járás | B15: 93 | C15: =VLOOKUP(CONCATENATE("2022",'2022_60'!A15),aktivnepesseg!$C$2:$D$2226,2,FALSE) -> 18276 | D15: 15455 | E15: =C15-D15 -> 2821 | F15: 2366 | G15: 702 | H15: 449 | I15: 362 | J15: 798 | K15: 459 | L15: 486 | M15: 258 | N15: 1077 | O15: 907 | P15: 2988 | Q15: 1745 | R15: 2856 | S15: =E15*E$5 -> 2821 | T15: =F15*F$5 -> 2188.55 | U15: =G15*G$5 -> 544.05 | V15: =H15*H$5 -> 291.85 | W15: =I15*I$5 -> 199.1 | X15: =J15*J$5 -> 359.1 | Y15: =K15*K$5 -> 149.175 | Z15: =L15*L$5 -> 85.05 | AA15: =M15*M$5 -> 12.9 | AB15: =SUM(S15:AA15)/$C15 -> 0.36390758
A16: Barcsi járás | B16: 140 | C16: =VLOOKUP(CONCATENATE("2022",'2022_60'!A16),aktivnepesseg!$C$2:$D$2226,2,FALSE) -> 13346 | D16: 10202 | E16: =C16-D16 -> 3144 | F16: 1732 | G16: 559 | H16: 297 | I16: 277 | J16: 589 | K16: 295 | L16: 329 | M16: 137 | N16: 599 | O16: 516 | P16: 1752 | Q16: 1086 | R16: 1941 | S16: =E16*E$5 -> 3144 | T16: =F16*F$5 -> 1602.1 | U16: =G16*G$5 -> 433.225 | V16: =H16*H$5 -> 193.05 | W16: =I16*I$5 -> 152.35 | X16: =J16*J$5 -> 265.05 | Y16: =K16*K$5 -> 95.875 | Z16: =L16*L$5 -> 57.575 | AA16: =M16*M$5 -> 6.85 | AB16: =SUM(S16:AA16)/$C16 -> 0.44583208
A17: Bátonyterenyei járás | B17: 117 | C17: =VLOOKUP(CONCATENATE("2022",'2022_60'!A17),aktivnepesseg!$C$2:$D$2226,2,FALSE) -> 11647 | D17: 9501 | E17: =C17-D17 -> 2146 | F17: 1134 | G17: 481 | H17: 224 | I17: 209 | J17: 401 | K17: 347 | L17: 342 | M17: 176 | N17: 655 | O17: 530 | P17: 1543 | Q17: 983 | R17: 2468 | S17: =E17*E$5 -> 2146 | T17: =F17*F$5 -> 1048.95 | U17: =G17*G$5 -> 372.775 | V17: =H17*H$5 -> 145.6 | W17: =I17*I$5 -> 114.95 | X17: =J17*J$5 -> 180.45 | Y17: =K17*K$5 -> 112.775 | Z17: =L17*L$5 -> 59.85 | AA17: =M17*M$5 -> 8.8 | AB17: =SUM(S17:AA17)/$C17 -> 0.35976217
A18: Békéscsabai járás | B18: 46 | C18: =VLOOKUP(CONCATENATE("2022",'2022_60'!A18),aktivnepesseg!$C$2:$D$2226,2,FALSE) -> 46299 | D18: 41219 | E18: =C18-D18 -> 5080 | F18: 6044 | G18: 1487 | H18: 868 | I18: 688 | J18: 1114 | K18: 962 | L18: 1146 | M18: 603 | N18: 2338 | O18: 2040 | P18: 7341 | Q18: 5127 | R18: 11453 | S18: =E18*E$5 -> 5080 | T18: =F18*F$5 -> 5590.7 | U18: =G18*G$5 -> 1152.425 | V18: =H18*H$5 -> 564.2 | W18: =I18*I$5 -> 378.4 | X18: =J18*J$5 -> 501.3 | Y18: =K18*K$5 -> 312.65 | Z18: =L18*L$5 -> 200.55 | AA18: =M18*M$5 -> 30.15 | AB18: =SUM(S18:AA18)/$C18 -> 0.29828668
... A203: Zirci járás | B203: 192 | C203: =VLOOKUP(CONCATENATE("2022",'2022_60'!A203),aktivnepesseg!$C$2:$D$2226,2,FALSE) -> 11752 | D203: 10275 | E203: =C203-D203 -> 1477 | F203: 1187 | G203: 310 | H203: 160 | I203: 179 | J203: 211 | K203: 203 | L203: 241 | M203: 152 | N203: 603 | O203: 612 | P203: 1979 | Q203: 1427 | R203: 2988 | S203: =E203*E$5 -> 1477 | T203: =F203*F$5 -> 1097.975 | U203: =G203*G$5 -> 240.25 | V203: =H203*H$5 -> 104 | W203: =I203*I$5 -> 98.45 | X203: =J203*J$5 -> 94.95 | Y203: =K203*K$5 -> 65.975 | Z203: =L203*L$5 -> 42.175 | AA203: =M203*M$5 -> 7.6 | AB203: =SUM(S203:AA203)/$C203 -> 0.27470856
A204: MAGYARORSZÁG totál | C204: =SUM(C7:C203) -> 6135730 | D204: =SUM(F204:R204) -> 5037935 | E204: =C204-D204 -> 1097795 | F204: =SUM(F7:F203) -> 674536 | G204: =SUM(G7:G203) -> 198235 | H204: =SUM(H7:H203) -> 119545 | I204: =SUM(I7:I203) -> 97366 | J204: =SUM(J7:J203) -> 162192 | K204: =SUM(K7:K203) -> 127191 | L204: =SUM(L7:L203) -> 146322 | M204: =SUM(M7:M203) -> 74168 | ... R204: =SUM(R7:R203) -> 1587544 | S204: =E204*E$5 -> 1097795 | T204: =F204*F$5 -> 623945.8 | U204: =G204*G$5 -> 153632.12 | V204: =H204*H$5 -> 77704.25 | W204: =I204*I$5 -> 53551.3 | X204: =J204*J$5 -> 72986.4 | Y204: =K204*K$5 -> 41337.075 | Z204: =L204*L$5 -> 25606.35 | AA204: =M204*M$5 -> 3708.4 | AB204: =SUM(S204:AA204)/$C204 -> 0.35045002
A205: Mo totál B változat | C205: =SUM(C7:C203) -> 6135730 | D205: =SUM(D7:D203) -> 5044045 | E205: =SUM(E7:E203) -> 1091685 | F205: =SUM(F7:F203) -> 674536 | G205: =SUM(G7:G203) -> 198235 | H205: =SUM(H7:H203) -> 119545 | I205: =SUM(I7:I203) -> 97366 | J205: =SUM(J7:J203) -> 162192 | ... R205: =SUM(R7:R203) -> 1587544
A206: Budapest | B206: 999 | C206: =VLOOKUP(CONCATENATE("2022",'2022_60'!A206),aktivnepesseg!$C$2:$D$2226,2,FALSE) -> 1105608 | D206: 868434 | E206: =C206-D206 -> 237174 | F206: 106637 | G206: 32983 | H206: 21750 | I206: 16251 | J206: 23490 | K206: 20882 | L206: 24854 | M206: 11987 | N206: 48268 | O206: 34305 | P206: 103104 | Q206: 73934 | R206: 349989 | S206: =E206*E$5 -> 237174 | T206: =F206*F$5 -> 98639.225 | U206: =G206*G$5 -> 25561.825 | V206: =H206*H$5 -> 14137.5 | W206: =I206*I$5 -> 8938.05 | X206: =J206*J$5 -> 10570.5 | Y206: =K206*K$5 -> 6786.65 | Z206: =L206*L$5 -> 4349.45 | AA206: =M206*M$5 -> 599.35 | AB206: =SUM(S206:AA206)/$C206 -> 0.36790305
A208: Mo N | C208: =C204 -> 6135730 | D208: =D204 -> 5037935 | E208: =E204 -> 1097795 | F208: =F204 -> 674536 | G208: =G204 -> 198235 | H208: =H204 -> 119545 | I208: =I204 -> 97366 | J208: =J204 -> 162192 | ... R208: =R204 -> 1587544
A209: Mo arány (adózókból) | F209: =F208/$D$208 -> 0.13389137 | G209: =G208/$D$208 -> 0.039348463 | H209: =H208/$D$208 -> 0.023728968 | I209: =I208/$D$208 -> 0.019326569 | J209: =J208/$D$208 -> 0.032194143 | K209: =K208/$D$208 -> 0.025246654 | L209: =L208/$D$208 -> 0.029044043 | M209: =M208/$D$208 -> 0.014721905 | ... R209: =R208/$D$208 -> 0.315118
A210: Mo kum arány (adózókból) | F210: =F209 -> 0.13389137 | G210: =G209+F210 -> 0.17323983 | H210: =H209+G210 -> 0.1969688 | I210: =I209+H210 -> 0.21629537 | J210: =J209+I210 -> 0.24848951 | K210: =K209+J210 -> 0.27373616 | L210: =L209+K210 -> 0.30278021 | M210: =M209+L210 -> 0.31750211 | N210: =N209+M210 -> 0.37601636 | ... R210: =R209+Q210 -> 1
A211: Mo arány (aktív korúakból) | D211: =D208/C208 -> 0.8210816 | E211: =E208/$C$208 -> 0.1789184 | F211: =F208/$C$208 -> 0.10993574 | G211: =G208/$C$208 -> 0.032308299 | H211: =H208/$C$208 -> 0.019483419 | I211: =I208/$C$208 -> 0.01586869 | J211: =J208/$C$208 -> 0.026434018 | K211: =K208/$C$208 -> 0.020729563 | L211: =L208/$C$208 -> 0.023847529 | ... R211: =R208/$C$208 -> 0.25873759
A212: Mo kum arány (aktív korúakból) | E212: =E211 -> 0.1789184 | F212: =F211+E212 -> 0.28885414 | G212: =G211+F212 -> 0.32116244 | H212: =H211+G212 -> 0.34064586 | I212: =I211+H212 -> 0.35651455 | J212: =J211+I212 -> 0.38294857 | K212: =K211+J212 -> 0.40367813 | L212: =L211+K212 -> 0.42752566 | M212: =M211+L212 -> 0.43961354 | ... R212: =R211+Q212 -> 1

Sheet 2024_60
A1: KÜSZÖB | D1: Adósáv alja | E1: 0 | F1: 0 | G1: =F2 -> 300 | H1: =G2 -> 600 | I1: =H2 -> 800 | J1: =I2 -> 1000 | K1: =J2 -> 1200 | L1: =K2 -> 1500 | M1: =L2 -> 1800 | N1: =M2 -> 2000 | ... T1: =S2 -> 20000 | U1: V03 - alacsonyabb küszöb | AG1: median60hoz
A2: 5000 | D2: Adósáv teteje | E2: 0 | F2: 300 | G2: 600 | H2: 800 | I2: 1000 | J2: 1200 | K2: 1500 | L2: 1800 | M2: 2000 | N2: 2500 | O2: 3000 | P2: 4000 | Q2: 5000 | R2: 10000 | S2: 20000 | U2: AKTÍV KORÚAKHOZ
A3: 3000 | D3: Adósáv közepe | E3: 0 | F3: =AVERAGE(F1:F2) -> 150 | G3: =AVERAGE(G1:G2) -> 450 | H3: =AVERAGE(H1:H2) -> 700 | I3: =AVERAGE(I1:I2) -> 900 | J3: =AVERAGE(J1:J2) -> 1100 | K3: =AVERAGE(K1:K2) -> 1350 | L3: =AVERAGE(L1:L2) -> 1650 | M3: =AVERAGE(M1:M2) -> 1900 | ... S3: =AVERAGE(S1:S2) -> 15000 | U3: 1 | V3: 1 | W3: 1 | X3: 1 | Y3: 1 | Z3: 1 | AA3: 1 | AB3: 1 | AC3: 1 | AD3: 1 | AE3: 1
A4: 2500 | D4: szorzóP1v0102 | E4: =($A$2-E3)/$A$2 -> 1 | F4: =($A$2-F3)/$A$2 -> 0.97 | G4: =($A$2-G3)/$A$2 -> 0.91 | H4: =($A$2-H3)/$A$2 -> 0.86 | I4: =($A$2-I3)/$A$2 -> 0.82 | J4: =($A$2-J3)/$A$2 -> 0.78 | K4: =($A$2-K3)/$A$2 -> 0.73 | L4: =($A$2-L3)/$A$2 -> 0.67 | ... Q4: =($A$2-Q3)/$A$2 -> 0.1 | U4: P1 részeredmények
A5: a szürkével jelöltek alternatív küszöbértékek | D5: szorzóP1v03 | E5: =($A$3-E3)/$A$3 -> 1 | F5: =($A$3-F3)/$A$3 -> 0.95 | G5: =($A$3-G3)/$A$3 -> 0.85 | H5: =($A$3-H3)/$A$3 -> 0.76666667 | I5: =($A$3-I3)/$A$3 -> 0.7 | J5: =($A$3-J3)/$A$3 -> 0.63333333 | K5: =($A$3-K3)/$A$3 -> 0.55 | L5: =($A$3-L3)/$A$3 -> 0.45 | ... P5: =($A$3-P3)/$A$3 -> -0.16666667
D6: szorzoP1median60 | E6: 1 | F6: =($A$4-F3)/$A$4 -> 0.94 | G6: =($A$4-G3)/$A$4 -> 0.82 | H6: =($A$4-H3)/$A$4 -> 0.72 | I6: =($A$4-I3)/$A$4 -> 0.64 | J6: =($A$4-J3)/$A$4 -> 0.56 | K6: =($A$4-K3)/$A$4 -> 0.46 | L6: =($A$4-L3)/$A$4 -> 0.34 | M6: =($A$4-M3)/$A$4 -> 0.24 | N6: =($A$4-N3)/$A$4 -> 0.1
B7: kod | C7: aktivkoru | D7: összes adózó | E7: NULLA sávon adózó aktív korú | F7: 2024 SZJA adófizető; 0-300 000 Ft éves összevont adóalapba tartozó jövedelmi sávon (fő) | G7: 2024 SZJA adófizető; 300 001-600 000 Ft éves összevont adóalapba tartozó jövedelmi sávon (fő) | H7: 2024 SZJA adófizető; 600 001-800 000 Ft éves összevont adóalapba tartozó jövedelmi sávon (fő) | I7: 2024 SZJA adófizető; 800 001-1 000 000 Ft éves összevont adóalapba tartozó jövedelmi sávon (fő) | J7: 2024 SZJA adófizető; 1 000 001-1 200 000 Ft éves összevont adóalapba tartozó jövedelmi sávon (fő) | K7: 2024 SZJA adófizető; 1 200 001-1 500 000 Ft éves összevont adóalapba tartozó jövedelmi sávon (fő) | L7: 2024 SZJA adófizető; 1 500 001-1 800 000 Ft éves összevont adóalapba tartozó jövedelmi sávon (fő) | M7: 2024 SZJA adófizető; 1 800 001-2 000 000 Ft éves összevont adóalapba tartozó jövedelmi sávon (fő) | N7: 2024 SZJA adófizető; 2 000 001-2 500 000 Ft éves összevont adóalapba tartozó jövedelmi sávon (fő) | O7: 2024 SZJA adófizető; 2 500 001-3 000 000 Ft éves összevont adóalapba tartozó jövedelmi sávon (fő) | P7: 2024 SZJA adófizető; 3 000 001-4 000 000 Ft éves összevont adóalapba tartozó jövedelmi sávon (fő) | Q7: 2024 SZJA adófizető; 4 000 001-5 000 000 Ft éves összevont adóalapba tartozó jövedelmi sávon (fő) | R7: 2024 SZJA adófizető; 5 000 001-10 000 000 Ft éves összevont adóalapba tartozó jövedelmi sávon (fő) | S7: 2024 SZJA adófizető; 10 000 001-20 000 000 Ft éves összevont adóalapba tartozó jövedelmi sávon (fő) | T7: 2024 SZJA adófizető; 20 000 000-X Ft éves összevont adóalapba tartozó jövedelmi sávon (fő) | U7: 0-0 sáv (új jöv sáv!) | V7: 0-300 | W7: 300-600 | X7: 600-800 | Y7: 800-1000 | Z7: 1000-1200 | AA7: 1200-1500 | AB7: 1500-1800 | AC7: 1800-2000 | AD7: 2000-2500 | AE7: 2500-3000 | AF7: P1 | AG7: 0-0 sáv (új jöv sáv!) | AH7: 0-300 | AI7: 300-600 | AJ7: 600-800 | AK7: 800-1000 | AL7: 1000-1200 | AM7: 1200-1500 | AN7: 1500-1800 | AO7: 1800-2000 | AP7: 2000-2500 | AQ7: P1
